<?xml version="1.0" ?>
<!-- =================================================================================== -->
<!-- |    This document was autogenerated by xacro from /mnt/c/users/sebas/catkin_ws/src/ppmrob/gazebo/urdf/drone.xacro | -->
<!-- |    EDITING THIS FILE BY HAND IS NOT RECOMMENDED                                 | -->
<!-- =================================================================================== -->
<robot name="custom_drone">
  <!-- Materials -->
  <material name="gray">
    <color rgba="0.5 0.5 0.5 1.0"/>
  </material>
  <material name="white">
    <color rgba="0.9 0.9 0.9 1.0"/>
  </material>
  <material name="red">
    <color rgba="1.0 0 0 1.0"/>
  </material>
  <material name="black">
    <color rgba="0.0274 0.0509 0.0509 1.0"/>
  </material>
  <material name="orange">
    <color rgba="1.0 0.4235294117647059 0.0392156862745098 1.0"/>
  </material>
  <material name="arm_material">
    <color rgba="0.0274 0.0509 0.0509 1.0"/>
  </material>
  <!-- Body link -->
  <link name="body">
    <visual>
      <origin xyz="0 0 0.01"/>
      <geometry>
        <box size="0.07 0.02 0.02"/>
      </geometry>
      <material name="white"/>
    </visual>
    <visual>
      <origin xyz="0 0 -0.01"/>
      <geometry>
        <box size="0.07 0.02 0.02"/>
      </geometry>
      <material name="white"/>
    </visual>
    <!-- <visual>
          <origin xyz="0.05 -0.05 0"/>
          <geometry>
              <cylinder length="0.01" radius="0.045"/>
          </geometry>
          <material name="Gazebo/black"/>
      </visual>
      <visual>
          <origin xyz="-0.05 0.05 0"/>
          <geometry>
              <cylinder length="0.01" radius="0.045"/>
          </geometry>
          <material name="black"/>
      </visual>
      <visual>
          <origin xyz="-0.05 -0.05 0"/>
          <geometry>
              <cylinder length="0.01" radius="0.045"/>
          </geometry>
          <material name="black"/>
      </visual>
      <visual>
          <origin xyz="0.05 0.05 0"/>
          <geometry>
              <cylinder length="0.01" radius="0.045"/>
          </geometry>
          <material name="black"/>
      </visual> -->
    <inertial>
      <mass value="0.1"/>
      <inertia ixx="0.000290833" ixy="0" ixz="0" iyy="0.00054" iyz="0" izz="0.000290833"/>
    </inertial>
    <collision name="collision">
      <geometry>
        <box size="0.18 0.18 0.05"/>
      </geometry>
    </collision>
  </link>
  <!-- Camera link -->
  <link name="camera_link">
    <visual>
      <origin xyz="0 0 0"/>
      <geometry>
        <sphere radius="0.01"/>
      </geometry>
      <material name="red"/>
    </visual>
    <collision>
      <geometry>
        <sphere radius="0.01"/>
      </geometry>
    </collision>
    <inertial>
      <mass value="1e-5"/>
      <inertia ixx="1e-6" ixy="0" ixz="0" iyy="1e-6" iyz="0" izz="1e-6"/>
    </inertial>
  </link>
  <!-- Fixed joint -->
  <joint name="camera_joint" type="fixed">
    <origin rpy="0 0 0" xyz="0.035 0 0"/>
    <!-- TODO fix origin -->
    <parent link="body"/>
    <child link="camera_link"/>
  </joint>
  <!-- Gazebo references -->
  <gazebo reference="body">
    <material>Gazebo/Orange</material>
  </gazebo>
  <link name="arm1">
    <visual>
      <origin rpy="0 1.5707963267948966 0.5235987755982988" xyz="0.09742785792574936 0.049999999999999996 0.005"/>
      <geometry>
        <cylinder length="0.15" radius="0.005"/>
      </geometry>
      <material name="arm_material"/>
    </visual>
    <collision>
      <origin rpy="0 1.5707963267948966 0.5235987755982988" xyz="0.09742785792574936 0.049999999999999996 0.005"/>
      <geometry>
        <cylinder length="0.15" radius="0.005"/>
      </geometry>
    </collision>
    <inertial>
      <mass value="0.01"/>
      <origin rpy="0 1.5707963267948966 0.5235987755982988" xyz="0.09742785792574936 0.049999999999999996 0.005"/>
      <inertia ixx="1.8812492474999998e-05" ixy="0.0" ixz="0.0" iyy="1.8812492474999998e-05" iyz="0.0" izz="1.2500000000000002e-07"/>
    </inertial>
  </link>
  <joint name="frame_arm1" type="fixed">
    <parent link="body"/>
    <child link="arm1"/>
  </joint>
  <gazebo reference="arm1">
    <material>Gazebo/Grey</material>
  </gazebo>
  <link name="arm3">
    <visual>
      <origin rpy="0 1.5707963267948966 2.617993877991494" xyz="-0.09742785792574933 0.05000000000000004 0.005"/>
      <geometry>
        <cylinder length="0.15" radius="0.005"/>
      </geometry>
      <material name="arm_material"/>
    </visual>
    <collision>
      <origin rpy="0 1.5707963267948966 2.617993877991494" xyz="-0.09742785792574933 0.05000000000000004 0.005"/>
      <geometry>
        <cylinder length="0.15" radius="0.005"/>
      </geometry>
    </collision>
    <inertial>
      <mass value="0.01"/>
      <origin rpy="0 1.5707963267948966 2.617993877991494" xyz="-0.09742785792574933 0.05000000000000004 0.005"/>
      <inertia ixx="1.8812492474999998e-05" ixy="0.0" ixz="0.0" iyy="1.8812492474999998e-05" iyz="0.0" izz="1.2500000000000002e-07"/>
    </inertial>
  </link>
  <joint name="frame_arm3" type="fixed">
    <parent link="body"/>
    <child link="arm3"/>
  </joint>
  <gazebo reference="arm3">
    <material>Gazebo/Grey</material>
  </gazebo>
  <link name="arm4">
    <visual>
      <origin rpy="0 1.5707963267948966 3.665191429188092" xyz="-0.09742785792574937 -0.049999999999999975 0.005"/>
      <geometry>
        <cylinder length="0.15" radius="0.005"/>
      </geometry>
      <material name="arm_material"/>
    </visual>
    <collision>
      <origin rpy="0 1.5707963267948966 3.665191429188092" xyz="-0.09742785792574937 -0.049999999999999975 0.005"/>
      <geometry>
        <cylinder length="0.15" radius="0.005"/>
      </geometry>
    </collision>
    <inertial>
      <mass value="0.01"/>
      <origin rpy="0 1.5707963267948966 3.665191429188092" xyz="-0.09742785792574937 -0.049999999999999975 0.005"/>
      <inertia ixx="1.8812492474999998e-05" ixy="0.0" ixz="0.0" iyy="1.8812492474999998e-05" iyz="0.0" izz="1.2500000000000002e-07"/>
    </inertial>
  </link>
  <joint name="frame_arm4" type="fixed">
    <parent link="body"/>
    <child link="arm4"/>
  </joint>
  <gazebo reference="arm4">
    <material>Gazebo/Grey</material>
  </gazebo>
  <link name="arm6">
    <visual>
      <origin rpy="0 1.5707963267948966 5.759586531581288" xyz="0.09742785792574937 -0.04999999999999997 0.005"/>
      <geometry>
        <cylinder length="0.15" radius="0.005"/>
      </geometry>
      <material name="arm_material"/>
    </visual>
    <collision>
      <origin rpy="0 1.5707963267948966 5.759586531581288" xyz="0.09742785792574937 -0.04999999999999997 0.005"/>
      <geometry>
        <cylinder length="0.15" radius="0.005"/>
      </geometry>
    </collision>
    <inertial>
      <mass value="0.01"/>
      <origin rpy="0 1.5707963267948966 5.759586531581288" xyz="0.09742785792574937 -0.04999999999999997 0.005"/>
      <inertia ixx="1.8812492474999998e-05" ixy="0.0" ixz="0.0" iyy="1.8812492474999998e-05" iyz="0.0" izz="1.2500000000000002e-07"/>
    </inertial>
  </link>
  <joint name="frame_arm6" type="fixed">
    <parent link="body"/>
    <child link="arm6"/>
  </joint>
  <gazebo reference="arm6">
    <material>Gazebo/Grey</material>
  </gazebo>
  <link name="propeller1">
    <visual>
      <origin rpy="0 0 0" xyz="0 0 0"/>
      <geometry>
        <!-- <cylinder radius="${propeller_radius_smaller}" length="${propeller_height}"/> -->
        <box size="0.011006666666666666 0.16000000000000003 0.001"/>
      </geometry>
      <material name="propeller_material"/>
    </visual>
    <collision>
      <origin rpy="0 0 0" xyz="0 0 0"/>
      <geometry>
        <!-- <cylinder radius="${propeller_radius_smaller}" length="${propeller_height}"/> -->
        <box size="0.011006666666666666 0.16000000000000003 0.001"/>
      </geometry>
    </collision>
    <inertial>
      <mass value="0.01"/>
      <origin rpy="0 0 0" xyz="0 0 0"/>
      <inertia ixx="1.2333328400000002e-05" ixy="0.0" ixz="0.0" iyy="1.2333328400000002e-05" iyz="0.0" izz="2.4500000000000006e-05"/>
    </inertial>
  </link>
  <joint name="arm1_propeller1" type="revolute">
    <parent link="arm1"/>
    <child link="propeller1"/>
    <origin rpy="0 0 0" xyz="0.15588457268119896 0.08999999999999998 0.015"/>
    <axis xyz="0 0 1"/>
    <limit effort="1000" lower="-2.0" upper="2.0" velocity="3.0"/>
  </joint>
  <!-- <transmission name="transmission_propeller${i}">
      <type>transmission_interface/SimpleTransmission</type>
      <joint name="arm${i}_propeller${i}">
        <hardwareInterface>EffortJointInterface</hardwareInterface>
      </joint>
      <actuator name="propeller${i}_motor">
        <hardwareInterface>EffortJointInterface</hardwareInterface>
        <mechanicalReduction>1</mechanicalReduction>
      </actuator>
    </transmission> -->
  <link name="propeller3">
    <visual>
      <origin rpy="0 0 0" xyz="0 0 0"/>
      <geometry>
        <!-- <cylinder radius="${propeller_radius_smaller}" length="${propeller_height}"/> -->
        <box size="0.011006666666666666 0.16000000000000003 0.001"/>
      </geometry>
      <material name="propeller_material"/>
    </visual>
    <collision>
      <origin rpy="0 0 0" xyz="0 0 0"/>
      <geometry>
        <!-- <cylinder radius="${propeller_radius_smaller}" length="${propeller_height}"/> -->
        <box size="0.011006666666666666 0.16000000000000003 0.001"/>
      </geometry>
    </collision>
    <inertial>
      <mass value="0.01"/>
      <origin rpy="0 0 0" xyz="0 0 0"/>
      <inertia ixx="1.2333328400000002e-05" ixy="0.0" ixz="0.0" iyy="1.2333328400000002e-05" iyz="0.0" izz="2.4500000000000006e-05"/>
    </inertial>
  </link>
  <joint name="arm3_propeller3" type="revolute">
    <parent link="arm3"/>
    <child link="propeller3"/>
    <origin rpy="0 0 0" xyz="-0.15588457268119893 0.09000000000000005 0.015"/>
    <axis xyz="0 0 1"/>
    <limit effort="1000" lower="-2.0" upper="2.0" velocity="3.0"/>
  </joint>
  <!-- <transmission name="transmission_propeller${i}">
      <type>transmission_interface/SimpleTransmission</type>
      <joint name="arm${i}_propeller${i}">
        <hardwareInterface>EffortJointInterface</hardwareInterface>
      </joint>
      <actuator name="propeller${i}_motor">
        <hardwareInterface>EffortJointInterface</hardwareInterface>
        <mechanicalReduction>1</mechanicalReduction>
      </actuator>
    </transmission> -->
  <link name="propeller4">
    <visual>
      <origin rpy="0 0 0" xyz="0 0 0"/>
      <geometry>
        <!-- <cylinder radius="${propeller_radius_smaller}" length="${propeller_height}"/> -->
        <box size="0.011006666666666666 0.16000000000000003 0.001"/>
      </geometry>
      <material name="propeller_material"/>
    </visual>
    <collision>
      <origin rpy="0 0 0" xyz="0 0 0"/>
      <geometry>
        <!-- <cylinder radius="${propeller_radius_smaller}" length="${propeller_height}"/> -->
        <box size="0.011006666666666666 0.16000000000000003 0.001"/>
      </geometry>
    </collision>
    <inertial>
      <mass value="0.01"/>
      <origin rpy="0 0 0" xyz="0 0 0"/>
      <inertia ixx="1.2333328400000002e-05" ixy="0.0" ixz="0.0" iyy="1.2333328400000002e-05" iyz="0.0" izz="2.4500000000000006e-05"/>
    </inertial>
  </link>
  <joint name="arm4_propeller4" type="revolute">
    <parent link="arm4"/>
    <child link="propeller4"/>
    <origin rpy="0 0 0" xyz="-0.15588457268119899 -0.08999999999999994 0.015"/>
    <axis xyz="0 0 1"/>
    <limit effort="1000" lower="-2.0" upper="2.0" velocity="3.0"/>
  </joint>
  <!-- <transmission name="transmission_propeller${i}">
      <type>transmission_interface/SimpleTransmission</type>
      <joint name="arm${i}_propeller${i}">
        <hardwareInterface>EffortJointInterface</hardwareInterface>
      </joint>
      <actuator name="propeller${i}_motor">
        <hardwareInterface>EffortJointInterface</hardwareInterface>
        <mechanicalReduction>1</mechanicalReduction>
      </actuator>
    </transmission> -->
  <link name="propeller6">
    <visual>
      <origin rpy="0 0 0" xyz="0 0 0"/>
      <geometry>
        <!-- <cylinder radius="${propeller_radius_smaller}" length="${propeller_height}"/> -->
        <box size="0.011006666666666666 0.16000000000000003 0.001"/>
      </geometry>
      <material name="propeller_material"/>
    </visual>
    <collision>
      <origin rpy="0 0 0" xyz="0 0 0"/>
      <geometry>
        <!-- <cylinder radius="${propeller_radius_smaller}" length="${propeller_height}"/> -->
        <box size="0.011006666666666666 0.16000000000000003 0.001"/>
      </geometry>
    </collision>
    <inertial>
      <mass value="0.01"/>
      <origin rpy="0 0 0" xyz="0 0 0"/>
      <inertia ixx="1.2333328400000002e-05" ixy="0.0" ixz="0.0" iyy="1.2333328400000002e-05" iyz="0.0" izz="2.4500000000000006e-05"/>
    </inertial>
  </link>
  <joint name="arm6_propeller6" type="revolute">
    <parent link="arm6"/>
    <child link="propeller6"/>
    <origin rpy="0 0 0" xyz="0.15588457268119899 -0.08999999999999994 0.015"/>
    <axis xyz="0 0 1"/>
    <limit effort="1000" lower="-2.0" upper="2.0" velocity="3.0"/>
  </joint>
  <!-- <transmission name="transmission_propeller${i}">
      <type>transmission_interface/SimpleTransmission</type>
      <joint name="arm${i}_propeller${i}">
        <hardwareInterface>EffortJointInterface</hardwareInterface>
      </joint>
      <actuator name="propeller${i}_motor">
        <hardwareInterface>EffortJointInterface</hardwareInterface>
        <mechanicalReduction>1</mechanicalReduction>
      </actuator>
    </transmission> -->
  <!-- Transmissions -->
  <transmission name="transmission_propeller1">
    <type>transmission_interface/SimpleTransmission</type>
    <joint name="arm1_propeller1">
      <hardwareInterface>EffortJointInterface</hardwareInterface>
    </joint>
    <actuator name="propeller1_motor">
      <hardwareInterface>EffortJointInterface</hardwareInterface>
      <mechanicalReduction>1</mechanicalReduction>
    </actuator>
  </transmission>
  <transmission name="transmission_propeller1">
    <type>transmission_interface/SimpleTransmission</type>
    <joint name="arm1_propeller1">
      <hardwareInterface>EffortJointInterface</hardwareInterface>
    </joint>
    <actuator name="propeller1_motor">
      <hardwareInterface>EffortJointInterface</hardwareInterface>
      <mechanicalReduction>1</mechanicalReduction>
    </actuator>
  </transmission>
  <transmission name="transmission_propeller3">
    <type>transmission_interface/SimpleTransmission</type>
    <joint name="arm3_propeller3">
      <hardwareInterface>EffortJointInterface</hardwareInterface>
    </joint>
    <actuator name="propeller3_motor">
      <hardwareInterface>EffortJointInterface</hardwareInterface>
      <mechanicalReduction>1</mechanicalReduction>
    </actuator>
  </transmission>
  <transmission name="transmission_propeller4">
    <type>transmission_interface/SimpleTransmission</type>
    <joint name="arm4_propeller4">
      <hardwareInterface>EffortJointInterface</hardwareInterface>
    </joint>
    <actuator name="propeller4_motor">
      <hardwareInterface>EffortJointInterface</hardwareInterface>
      <mechanicalReduction>1</mechanicalReduction>
    </actuator>
  </transmission>
  <transmission name="transmission_propeller6">
    <type>transmission_interface/SimpleTransmission</type>
    <joint name="arm6_propeller6">
      <hardwareInterface>EffortJointInterface</hardwareInterface>
    </joint>
    <actuator name="propeller6_motor">
      <hardwareInterface>EffortJointInterface</hardwareInterface>
      <mechanicalReduction>1</mechanicalReduction>
    </actuator>
  </transmission>
  <!-- Tello plugin for Gazebo -->
  <gazebo>
    <!-- <gazebo>
        <plugin name="gazebo_ros_control" filename="libgazebo_ros_control.so">
          <robotNamespace>gazebo</robotNamespace>
          <robotSimType>gazebo_ros_control/DefaultRobotHWSim</robotSimType>
        </plugin>
      </gazebo> -->
    <!-- <plugin name="ControlPlugin" filename="libcontrol_plugin.so">
          <parameter name="use_sim_time" type="bool">1</parameter>
          <link_name>body</link_name>
          <center_of_mass>0 0 0</center_of_mass>
      </plugin>
      <plugin name="BatteryPlugin" filename="libbattery_plugin.so">
          <parameter name="use_sim_time" type="bool">1</parameter>
          <link_name>body</link_name>
          <center_of_mass>0 0 0</center_of_mass>
      </plugin> -->
    <plugin filename="libgazebo_ros_control.so" name="gazebo_ros_control">
      <robotNamespace>gazebo</robotNamespace>
      <controlPeriod>0.002</controlPeriod>
      <robotSimType>gazebo_ros_control/DefaultRobotHWSim</robotSimType>
      <legacyModeNS>true</legacyModeNS>
      <alwaysOn>true</alwaysOn>
      <updateRate>1000.0</updateRate>
      <joint name="arm1_propeller1">
        <pid>
          <p>1000.0</p>
          <i>0.01</i>
          <d>0.01</d>
          <iMax>1000.0</iMax>
          <iMin>-1000.0</iMin>
          <cmdMax>1000.0</cmdMax>
          <cmdMin>-1000.0</cmdMin>
        </pid>
      </joint>
      <joint name="arm3_propeller3">
        <pid>
          <p>1000.0</p>
          <i>0.01</i>
          <d>0.01</d>
          <iMax>1000.0</iMax>
          <iMin>-1000.0</iMin>
          <cmdMax>1000.0</cmdMax>
          <cmdMin>-1000.0</cmdMin>
        </pid>
      </joint>
      <joint name="arm4_propeller4">
        <pid>
          <p>1000.0</p>
          <i>0.01</i>
          <d>0.01</d>
          <iMax>1000.0</iMax>
          <iMin>-1000.0</iMin>
          <cmdMax>1000.0</cmdMax>
          <cmdMin>-1000.0</cmdMin>
        </pid>
      </joint>
      <joint name="arm6_propeller6">
        <pid>
          <p>1000.0</p>
          <i>0.01</i>
          <d>0.01</d>
          <iMax>1000.0</iMax>
          <iMin>-1000.0</iMin>
          <cmdMax>1000.0</cmdMax>
          <cmdMin>-1000.0</cmdMin>
        </pid>
      </joint>
    </plugin>
  </gazebo>
  <gazebo reference="camera_link">
    <sensor name="camera1" type="camera">
      <update_rate>30.0</update_rate>
      <camera name="head">
        <horizontal_fov>1.3962634</horizontal_fov>
        <image>
          <width>800</width>
          <height>800</height>
          <format>R8G8B8</format>
        </image>
        <clip>
          <near>0.02</near>
          <far>300</far>
        </clip>
        <noise>
          <type>gaussian</type>
          <mean>0.0</mean>
          <stddev>0.007</stddev>
        </noise>
      </camera>
      <plugin filename="libgazebo_ros_camera.so" name="camera_controller">
        <alwaysOn>true</alwaysOn>
        <updateRate>0.0</updateRate>
        <cameraName>gazebo/camera1</cameraName>
        <imageTopicName>image_raw</imageTopicName>
        <cameraInfoTopicName>camera_info</cameraInfoTopicName>
        <frameName>camera_link</frameName>
        <hackBaseline>0.07</hackBaseline>
        <distortionK1>0.0</distortionK1>
        <distortionK2>0.0</distortionK2>
        <distortionK3>0.0</distortionK3>
        <distortionT1>0.0</distortionT1>
        <distortionT2>0.0</distortionT2>
      </plugin>
    </sensor>
  </gazebo>
</robot>

